Workbook

Sheet Main
A1: Number | B1: ID | C1: Item0 | D1: Item1 | E1: Item2 | F1: Item3 | G1: Item4 | H1: Item5 | I1: Item6 | J1: normScore | K1: Excluded | L1: Row | M1: Column inside row | N1: Possible answers (except item 0)
C2: Sum total intensity Huge variability across samples? | D2: PVC | E2: Correlation | F2: MA plot | G2: MeanSD plot | H2: RLE plot | I2: Total intensity distribution | J2: Global | N2: Log
A3: 75 | B3: PXD016670 | C3: Yes | D3: =Item1!K2 -> Quantile | E3: =Item2!K2 -> CyclicLoess | F3: =Item3!K2 -> Quantile | G3: =Item4!K2 -> Quantile | H3: =Item5!K2 -> Quantile | I3: =Item6!K2 -> Quantile | J3: Quantile;CyclicLoess;RLR | K3: Log | L3: 1 | M3: 1 | N3: Mean
A4: 11 | B4: PXD038236 | C4: Yes | D4: =Item1!K3 -> Quantile | E4: =Item2!K3 -> CyclicLoess | F4: =Item3!K3 -> Median | G4: =Item4!K3 -> Quantile | H4: =Item5!K3 -> CyclicLoess | I4: =Item6!K3 -> Quantile | J4: Median;Quantile | K4: RLR | L4: 1 | M4: 2 | N4: Median
A5: 17 | B5: PXD054553 | C5: Yes | D5: =Item1!K4 -> Quantile | E5: =Item2!K4 -> Quantile | F5: =Item3!K4 -> CyclicLoess | G5: =Item4!K4 -> Quantile | H5: =Item5!K4 -> Quantile | I5: =Item6!K4 -> Quantile | J5: Median;Quantile | K5: RLR | L5: 1 | M5: 3 | N5: Total Intensity
A6: 98 | B6: PXD005847 | C6: Yes | D6: =Item1!K5 -> CyclicLoess | E6: =Item2!K5 -> Log | F6: =Item3!K5 -> RLR | G6: =Item4!K5 -> Quantile | H6: =Item5!K5 -> CyclicLoess | I6: =Item6!K5 -> Quantile | J6: Quantile;CyclicLoess;RLR | L6: 1 | M6: 4 | N6: Quantile
A7: 72 | B7: PXD012431 | C7: Yes | D7: =Item1!K6 -> Median | E7: =Item2!K6 -> CyclicLoess | F7: =Item3!K6 -> Quantile | G7: =Item4!K6 -> Quantile | H7: =Item5!K6 -> CyclicLoess | I7: =Item6!K6 -> Quantile | J7: Quantile | K7: Log;RLR | L7: 1 | M7: 5 | N7: CyclicLoess
A8: 15 | B8: PXD022614 | C8: Yes | D8: =Item1!K7 -> Quantile | E8: =Item2!K7 -> CyclicLoess | F8: =Item3!K7 -> Median | G8: =Item4!K7 -> Quantile | H8: =Item5!K7 -> Median | I8: =Item6!K7 -> Quantile | J8: Median;Quantile | K8: Log | L8: 1 | M8: 6 | N8: VSN
A9: 5 | B9: PXD066495 | C9: No | D9: =Item1!K8 -> Median | E9: =Item2!K8 -> CyclicLoess | F9: =Item3!K8 -> Median | G9: =Item4!K8 -> Log | H9: =Item5!K8 -> Median | I9: =Item6!K8 -> Median | J9: Median;Mean;TI | L9: 2 | M9: 1 | N9: RLR
A10: 6 | B10: PXD065898 | C10: Yes | D10: =Item1!K9 -> Median | E10: =Item2!K9 -> Log | F10: =Item3!K9 -> Log | G10: =Item4!K9 -> Log | H10: =Item5!K9 -> CyclicLoess | I10: =Item6!K9 -> Median | J10: Median | K10: Log | L10: 2 | M10: 2
A11: 96 | B11: PXD062946 | C11: Yes | D11: =Item1!K10 -> CyclicLoess | E11: =Item2!K10 -> CyclicLoess | F11: =Item3!K10 -> Quantile | G11: =Item4!K10 -> Log | H11: =Item5!K10 -> CyclicLoess | I11: =Item6!K10 -> Quantile | J11: Quantile;CyclicLoess | K11: Log | L11: 2 | M11: 3 | N11: Answers item0
A12: 4 | B12: PXD031710 | C12: Yes | D12: =Item1!K11 -> Median | E12: =Item2!K11 -> CyclicLoess | F12: =Item3!K11 -> Quantile | G12: =Item4!K11 -> Quantile | H12: =Item5!K11 -> Quantile | I12: =Item6!K11 -> Quantile | J12: Quantile;Median | K12: Log | L12: 2 | M12: 4 | N12: Yes
A13: 20 | B13: PXD047566 | C13: Yes | D13: =Item1!K12 -> Quantile | E13: =Item2!K12 -> CyclicLoess | F13: =Item3!K12 -> Log | G13: =Item4!K12 -> Quantile | H13: =Item5!K12 -> Quantile | I13: =Item6!K12 -> Quantile | J13: Median;Quantile | K13: Log | L13: 2 | M13: 5 | N13: No
A14: 76 | B14: PXD019139 | C14: No | D14: =Item1!K13 -> Quantile | E14: =Item2!K13 -> CyclicLoess | F14: =Item3!K13 -> Log | G14: =Item4!K13 -> Log | H14: =Item5!K13 -> Quantile | I14: =Item6!K13 -> Median | J14: Median | K14: Log | L14: 2 | M14: 6
A15: 79 | B15: PXD041237 | C15: Yes | D15: =Item1!K14 -> Median | E15: =Item2!K14 -> CyclicLoess | F15: =Item3!K14 -> RLR | G15: =Item4!K14 -> Quantile | H15: =Item5!K14 -> Median | I15: =Item6!K14 -> Quantile | J15: Quantile;CyclicLoess | K15: Log | L15: 3 | M15: 1
A16: 80 | B16: PXD039491 | C16: Yes | D16: =Item1!K15 -> CyclicLoess | E16: =Item2!K15 -> Log | F16: =Item3!K15 -> Quantile | G16: =Item4!K15 -> Log | H16: =Item5!K15 -> CyclicLoess | I16: =Item6!K15 -> Quantile | J16: Quantile;Median;CyclicLoess | K16: Log | L16: 3 | M16: 2
A17: 85 | B17: PXD038019 | C17: Yes | D17: =Item1!K16 -> Quantile | E17: =Item2!K16 -> Log | F17: =Item3!K16 -> Quantile | G17: =Item4!K16 -> Quantile | H17: =Item5!K16 -> Quantile | I17: =Item6!K16 -> Quantile | J17: Quantile;Median | K17: Log;RLR | L17: 3 | M17: 3
A18: 12 | B18: PXD062018 | C18: Yes | D18: =Item1!K17 -> Median | E18: =Item2!K17 -> CyclicLoess | F18: =Item3!K17 -> Quantile | G18: =Item4!K17 -> Log | H18: =Item5!K17 -> Quantile | I18: =Item6!K17 -> Median | J18: CyclicLoess;Quantile | K18: Mean;TI | L18: 3 | M18: 4
A19: 16 | B19: PXD019504 | C19: Yes | D19: =Item1!K18 -> Quantile | E19: =Item2!K18 -> Log | F19: =Item3!K18 -> RLR | G19: =Item4!K18 -> Quantile | H19: =Item5!K18 -> CyclicLoess | I19: =Item6!K18 -> Quantile | J19: RLR | K19: Mean;TI;Log | L19: 3 | M19: 5
A20: 18 | B20: PXD054636 | C20: Yes | D20: =Item1!K19 -> Quantile | E20: =Item2!K19 -> CyclicLoess | F20: =Item3!K19 -> Median | G20: =Item4!K19 -> Quantile | H20: =Item5!K19 -> CyclicLoess | I20: =Item6!K19 -> Median | J20: Median | K20: Quantile | L20: 3 | M20: 6
A21: 77 | B21: PXD019103 | C21: Yes | D21: =Item1!K20 -> Median | E21: =Item2!K20 -> CyclicLoess | F21: =Item3!K20 -> Quantile | G21: =Item4!K20 -> Quantile | H21: =Item5!K20 -> CyclicLoess | I21: =Item6!K20 -> Quantile | J21: Quantile;CyclicLoess | K21: Log;Mean;TI | L21: 4 | M21: 1
A22: 99 | B22: PXD030595 | C22: Yes | D22: =Item1!K21 -> Log | E22: =Item2!K21 -> Log | F22: =Item3!K21 -> Median | G22: =Item4!K21 -> Quantile | H22: =Item5!K21 -> RLR | I22: =Item6!K21 -> Quantile | J22: Quantile | L22: 4 | M22: 2
A23: 19 | B23: PXD054817 | C23: Yes | D23: =Item1!K22 -> CyclicLoess | E23: =Item2!K22 -> CyclicLoess | F23: =Item3!K22 -> CyclicLoess | G23: =Item4!K22 -> Quantile | H23: =Item5!K22 -> CyclicLoess | I23: =Item6!K22 -> Quantile | J23: CyclicLoess;Quantile | K23: Log | L23: 4 | M23: 3
A24: 41 | B24: PXD054817.2 | C24: Yes | D24: =Item1!K23 -> Median | E24: =Item2!K23 -> CyclicLoess | F24: =Item3!K23 -> Quantile | G24: =Item4!K23 -> Quantile | H24: =Item5!K23 -> CyclicLoess | I24: =Item6!K23 -> Quantile | J24: Quantile | K24: Mean;TI;Log | L24: 4 | M24: 4
A25: 73 | B25: PXD018900 | C25: Yes | D25: =Item1!K24 -> Median | E25: =Item2!K24 -> Median | F25: =Item3!K24 -> RLR | G25: =Item4!K24 -> Log | H25: =Item5!K24 -> CyclicLoess | I25: =Item6!K24 -> CyclicLoess | J25: CyclicLoess;RLR | K25: Log | L25: 4 | M25: 5
A26: 74 | B26: PXD019296 | C26: Yes | D26: =Item1!K25 -> RLR | E26: =Item2!K25 -> CyclicLoess | F26: =Item3!K25 -> Quantile | G26: =Item4!K25 -> Quantile | H26: =Item5!K25 -> CyclicLoess | I26: =Item6!K25 -> Quantile | J26: Quantile | K26: Log;Median | L26: 5 | M26: 1
A27: 82 | B27: PXD022038 | C27: Yes | D27: =Item1!K26 -> Log | E27: =Item2!K26 -> Log | F27: =Item3!K26 -> TI | G27: =Item4!K26 -> Log | H27: =Item5!K26 -> CyclicLoess | I27: =Item6!K26 -> TI | J27: TI | K27: Log | L27: 5 | M27: 2
A28: 83 | B28: PXD007182 | C28: No | D28: =Item1!K27 -> Log | E28: =Item2!K27 -> CyclicLoess | F28: =Item3!K27 -> Median | G28: =Item4!K27 -> Log | H28: =Item5!K27 -> Quantile | I28: =Item6!K27 -> Log | J28: Median | L28: 5 | M28: 3
A29: 84 | B29: PXD042498 | C29: Yes | D29: =Item1!K28 -> Median | E29: =Item2!K28 -> CyclicLoess | F29: =Item3!K28 -> Median | G29: =Item4!K28 -> Log | H29: =Item5!K28 -> Median | I29: =Item6!K28 -> Median | J29: Median | K29: Log | L29: 5 | M29: 4
A30: 88 | B30: PXD005025 | C30: Yes | D30: =Item1!K29 -> Quantile | E30: =Item2!K29 -> CyclicLoess | F30: =Item3!K29 -> Median | G30: =Item4!K29 -> Quantile | H30: =Item5!K29 -> CyclicLoess | I30: =Item6!K29 -> CyclicLoess | J30: Median;Quantile | K30: Log | L30: 5 | M30: 5
A31: 90 | B31: PXD022701 | C31: No | D31: =Item1!K30 -> Quantile | E31: =Item2!K30 -> CyclicLoess | F31: =Item3!K30 -> Quantile | G31: =Item4!K30 -> Median | H31: =Item5!K30 -> Median | I31: =Item6!K30 -> Median | J31: Quantile;CyclicLoess | K31: Log | L31: 5 | M31: 6
A32: 93 | B32: PXD015470 | C32: Yes | D32: =Item1!K31 -> Quantile | E32: =Item2!K31 -> CyclicLoess | F32: =Item3!K31 -> CyclicLoess | G32: =Item4!K31 -> Quantile | H32: =Item5!K31 -> Quantile | I32: =Item6!K31 -> Quantile | J32: Quantile | K32: Log | L32: 6 | M32: 1
A33: 95 | B33: PXD020245 | C33: Yes | D33: =Item1!K32 -> Quantile | E33: =Item2!K32 -> CyclicLoess | F33: =Item3!K32 -> Log | G33: =Item4!K32 -> Quantile | H33: =Item5!K32 -> Median | I33: =Item6!K32 -> Quantile | J33: Median;Quantile | K33: Log | L33: 6 | M33: 2
A34: 7 | B34: PXD064630 | C34: Yes | D34: =Item1!K33 -> Quantile | E34: =Item2!K33 -> CyclicLoess | F34: =Item3!K33 -> Log | G34: =Item4!K33 -> Median | H34: =Item5!K33 -> Median | I34: =Item6!K33 -> Median | J34: Median | K34: Log | L34: 6 | M34: 3
A35: 13 | B35: PXD033101 | C35: Yes | D35: =Item1!K34 -> RLR | E35: =Item2!K34 -> Median | F35: =Item3!K34 -> Log | G35: =Item4!K34 -> Quantile | H35: =Item5!K34 -> CyclicLoess | I35: =Item6!K34 -> RLR | J35: CyclicLoess;RLR | K35: Log;Mean;TI | L35: 6 | M35: 4
A36: 78 | B36: PXD029776 | C36: No | D36: =Item1!K35 -> Median | E36: =Item2!K35 -> CyclicLoess | F36: =Item3!K35 -> Median | G36: =Item4!K35 -> Quantile | H36: =Item5!K35 -> Median | I36: =Item6!K35 -> Median | J36: Median;Quantile | K36: Log | L36: 6 | M36: 5
A37: 81 | B37: PXD040288 | C37: Yes | D37: =Item1!K36 -> Median | E37: =Item2!K36 -> CyclicLoess | F37: =Item3!K36 -> Quantile | G37: =Item4!K36 -> Quantile | H37: =Item5!K36 -> Median | I37: =Item6!K36 -> Median | J37: Median;Quantile | K37: Log | L37: 6 | M37: 6
A38: 86 | B38: PXD069093 | C38: Yes | D38: =Item1!K37 -> RLR | E38: =Item2!K37 -> CyclicLoess | F38: =Item3!K37 -> RLR | G38: =Item4!K37 -> Quantile | H38: =Item5!K37 -> CyclicLoess | I38: =Item6!K37 -> Quantile | J38: Quantile;CyclicLoess | K38: Log;Mean;TI | L38: 7 | M38: 1
A39: 87 | B39: PXD068908 | C39: Yes | D39: =Item1!K38 -> Median | E39: =Item2!K38 -> Log | F39: =Item3!K38 -> Quantile | G39: =Item4!K38 -> VSN | H39: =Item5!K38 -> Median | I39: =Item6!K38 -> Quantile | J39: Median;Quantile | K39: RLR;Log | L39: 7 | M39: 2
A40: 89 | B40: PXD010785 | C40: Yes | D40: =Item1!K39 -> Quantile | E40: =Item2!K39 -> CyclicLoess | F40: =Item3!K39 -> Quantile | G40: =Item4!K39 -> Quantile | H40: =Item5!K39 -> Median | I40: =Item6!K39 -> Median | J40: Median | K40: Log | L40: 7 | M40: 3
...

Sheet Item1
A1: Number | B1: ID | C1: Log | D1: Mean | E1: Median | F1: TI | G1: Quantile | H1: CyclicLoess | I1: VSN | J1: RLR | K1: Final
A2: 75 | B2: PXD016670 | C2: 6 | D2: 5 | E2: 4 | F2: 5 | G2: 1 | H2: 4 | I2: 3 | J2: 2 | K2: Quantile
A3: 11 | B3: PXD038236 | C3: 2 | D3: 3 | E3: 2 | F3: 3 | G3: 1 | H3: 1 | I3: 1 | J3: 4 | K3: Quantile
A4: 17 | B4: PXD054553 | C4: 6 | D4: 5 | E4: 3 | F4: 5 | G4: 1 | H4: 4 | I4: 2 | J4: 7 | K4: Quantile
A5: 98 | B5: PXD005847 | C5: 7 | D5: 6 | E5: 5 | F5: 6 | G5: 2 | H5: 1 | I5: 4 | J5: 3 | K5: CyclicLoess
A6: 72 | B6: PXD012431 | C6: 8 | D6: 6 | E6: 1 | F6: 5 | G6: 4 | H6: 3 | I6: 2 | J6: 7 | K6: Median
A7: 15 | B7: PXD022614 | C7: 8 | D7: 6 | E7: 4 | F7: 7 | G7: 1 | H7: 3 | I7: 5 | J7: 2 | K7: Quantile
A8: 5 | B8: PXD066495 | C8: 2 | D8: 1 | E8: 1 | F8: 1 | G8: 1 | H8: 1 | I8: 1 | J8: 1 | K8: Median
A9: 6 | B9: PXD065898 | C9: 3 | D9: 2 | E9: 1 | F9: 2 | G9: 1 | H9: 1 | I9: 1 | J9: 1 | K9: Median
A10: 96 | B10: PXD062946 | C10: 7 | D10: 6 | E10: 4 | F10: 6 | G10: 3 | H10: 1 | I10: 2 | J10: 5 | K10: CyclicLoess
A11: 4 | B11: PXD031710 | C11: 6 | D11: 5 | E11: 1 | F11: 5 | G11: 2 | H11: 3 | I11: 3 | J11: 4 | K11: Median
A12: 20 | B12: PXD047566 | C12: 5 | D12: 4 | E12: 4 | F12: 4 | G12: 1 | H12: 2 | I12: 2 | J12: 3 | K12: Quantile
A13: 76 | B13: PXD019139 | C13: 3 | D13: 2 | E13: 2 | F13: 2 | G13: 1 | H13: 2 | I13: 2 | J13: 2 | K13: Quantile
... A101: 38 | B101: PXD060921 | C101: 5 | D101: 7 | E101: 3 | F101: 7 | G101: 2 | H101: 4 | I101: 1 | J101: 6 | K101: VSN

Sheet Item2
A1: Number | B1: ID | C1: Log | D1: Mean | E1: Median | F1: TI | G1: Quantile | H1: CyclicLoess | I1: VSN | J1: RLR | K1: Final
A2: 75 | B2: PXD016670 | C2: 2 | D2: 2 | E2: 2 | F2: 2 | G2: 2 | H2: 1 | I2: 2 | J2: 2 | K2: CyclicLoess
A3: 11 | B3: PXD038236 | C3: 2 | D3: 2 | E3: 2 | F3: 2 | G3: 2 | H3: 1 | I3: 2 | J3: 2 | K3: CyclicLoess
A4: 17 | B4: PXD054553 | C4: 2 | D4: 2 | E4: 2 | F4: 2 | G4: 1 | H4: 2 | I4: 2 | J4: 2 | K4: Quantile
A5: 98 | B5: PXD005847 | C5: 1 | D5: 1 | E5: 1 | F5: 1 | G5: 1 | H5: 2 | I5: 1 | J5: 1 | K5: Log
A6: 72 | B6: PXD012431 | C6: 2 | D6: 2 | E6: 2 | F6: 2 | G6: 2 | H6: 1 | I6: 2 | J6: 2 | K6: CyclicLoess
A7: 15 | B7: PXD022614 | C7: 2 | D7: 2 | E7: 2 | F7: 2 | G7: 2 | H7: 1 | I7: 2 | J7: 2 | K7: CyclicLoess
A8: 5 | B8: PXD066495 | C8: 2 | D8: 2 | E8: 2 | F8: 2 | G8: 2 | H8: 1 | I8: 2 | J8: 2 | K8: CyclicLoess
A9: 6 | B9: PXD065898 | C9: 1 | D9: 1 | E9: 1 | F9: 1 | G9: 1 | H9: 2 | I9: 1 | J9: 1 | K9: Log
A10: 96 | B10: PXD062946 | C10: 2 | D10: 2 | E10: 2 | F10: 2 | G10: 2 | H10: 1 | I10: 2 | J10: 2 | K10: CyclicLoess
A11: 4 | B11: PXD031710 | C11: 2 | D11: 2 | E11: 2 | F11: 2 | G11: 2 | H11: 1 | I11: 2 | J11: 2 | K11: CyclicLoess
A12: 20 | B12: PXD047566 | C12: 2 | D12: 2 | E12: 2 | F12: 2 | G12: 2 | H12: 1 | I12: 2 | J12: 2 | K12: CyclicLoess
A13: 76 | B13: PXD019139 | C13: 2 | D13: 2 | E13: 2 | F13: 2 | G13: 2 | H13: 1 | I13: 2 | J13: 2 | K13: CyclicLoess
... A101: 38 | B101: PXD060921 | C101: 2 | D101: 2 | E101: 2 | F101: 2 | G101: 2 | H101: 1 | I101: 2 | J101: 2 | K101: CyclicLoess

Sheet Item3
A1: Number | B1: ID | C1: Log | D1: Mean | E1: Median | F1: TI | G1: Quantile | H1: CyclicLoess | I1: VSN | J1: RLR | K1: Final
A2: 75 | B2: PXD016670 | C2: 4 | D2: 4 | E2: 3 | F2: 4 | G2: 1 | H2: 2 | I2: 3 | J2: 2 | K2: Quantile
A3: 11 | B3: PXD038236 | C3: 2 | D3: 2 | E3: 1 | F3: 2 | G3: 1 | H3: 2 | I3: 2 | J3: 3 | K3: Median
A4: 17 | B4: PXD054553 | C4: 4 | D4: 5 | E4: 3 | F4: 5 | G4: 3 | H4: 1 | I4: 2 | J4: 1 | K4: CyclicLoess
A5: 98 | B5: PXD005847 | C5: 4 | D5: 6 | E5: 5 | F5: 6 | G5: 3 | H5: 2 | I5: 5 | J5: 1 | K5: RLR
A6: 72 | B6: PXD012431 | C6: 3 | D6: 3 | E6: 2 | F6: 3 | G6: 1 | H6: 4 | I6: 2 | J6: 5 | K6: Quantile
A7: 15 | B7: PXD022614 | C7: 3 | D7: 2 | E7: 1 | F7: 2 | G7: 1 | H7: 1 | I7: 1 | J7: 1 | K7: Median
A8: 5 | B8: PXD066495 | C8: 2 | D8: 1 | E8: 1 | F8: 1 | G8: 1 | H8: 1 | I8: 1 | J8: 1 | K8: Median
A9: 6 | B9: PXD065898 | C9: 1 | D9: 1 | E9: 1 | F9: 1 | G9: 1 | H9: 1 | I9: 1 | J9: 1 | K9: Log
A10: 96 | B10: PXD062946 | C10: 3 | D10: 2 | E10: 2 | F10: 2 | G10: 1 | H10: 1 | I10: 2 | J10: 2 | K10: Quantile
A11: 4 | B11: PXD031710 | C11: 4 | D11: 4 | E11: 4 | F11: 4 | G11: 1 | H11: 2 | I11: 4 | J11: 3 | K11: Quantile
A12: 20 | B12: PXD047566 | C12: 1 | D12: 1 | E12: 1 | F12: 1 | G12: 1 | H12: 1 | I12: 1 | J12: 1 | K12: Log
A13: 76 | B13: PXD019139 | C13: 1 | D13: 1 | E13: 1 | F13: 1 | G13: 1 | H13: 1 | I13: 1 | J13: 1 | K13: Log
... A101: 38 | B101: PXD060921 | C101: 1 | D101: 1 | E101: 1 | F101: 1 | G101: 1 | H101: 1 | I101: 1 | J101: 1 | K101: Log

Sheet Item4
A1: Number | B1: ID | C1: Log | D1: Mean | E1: Median | F1: TI | G1: Quantile | H1: CyclicLoess | I1: VSN | J1: RLR | K1: Final
A2: 75 | B2: PXD016670 | C2: 6 | D2: 5 | E2: 4 | F2: 5 | G2: 1 | H2: 2 | I2: 6 | J2: 3 | K2: Quantile
A3: 11 | B3: PXD038236 | C3: 3 | D3: 3 | E3: 2 | F3: 3 | G3: 1 | H3: 5 | I3: 4 | J3: 6 | K3: Quantile
A4: 17 | B4: PXD054553 | C4: 6 | D4: 4 | E4: 2 | F4: 4 | G4: 1 | H4: 5 | I4: 3 | J4: 7 | K4: Quantile
A5: 98 | B5: PXD005847 | C5: 6 | D5: 6 | E5: 4 | F5: 6 | G5: 1 | H5: 2 | I5: 5 | J5: 3 | K5: Quantile
A6: 72 | B6: PXD012431 | C6: 5 | D6: 5 | E6: 3 | F6: 5 | G6: 1 | H6: 2 | I6: 3 | J6: 4 | K6: Quantile
A7: 15 | B7: PXD022614 | C7: 5 | D7: 6 | E7: 4 | F7: 6 | G7: 1 | H7: 3 | I7: 5 | J7: 2 | K7: Quantile
A8: 5 | B8: PXD066495 | C8: 1 | D8: 1 | E8: 1 | F8: 1 | G8: 1 | H8: 1 | I8: 1 | J8: 1 | K8: Log
A9: 6 | B9: PXD065898 | C9: 1 | D9: 3 | E9: 2 | F9: 3 | G9: 1 | H9: 1 | I9: 4 | J9: 2 | K9: Log
A10: 96 | B10: PXD062946 | C10: 1 | D10: 4 | E10: 1 | F10: 4 | G10: 1 | H10: 3 | I10: 1 | J10: 2 | K10: Log
A11: 4 | B11: PXD031710 | C11: 4 | D11: 5 | E11: 4 | F11: 5 | G11: 1 | H11: 2 | I11: 6 | J11: 3 | K11: Quantile
A12: 20 | B12: PXD047566 | C12: 4 | D12: 4 | E12: 4 | F12: 4 | G12: 1 | H12: 2 | I12: 3 | J12: 3 | K12: Quantile
A13: 76 | B13: PXD019139 | C13: 1 | D13: 2 | E13: 1 | F13: 2 | G13: 1 | H13: 1 | I13: 2 | J13: 1 | K13: Log
... A101: 38 | B101: PXD060921 | C101: 2 | D101: 2 | E101: 2 | F101: 2 | G101: 1 | H101: 2 | I101: 1 | J101: 3 | K101: Log

Sheet Item5
A1: Number | B1: ID | C1: Log | D1: Mean | E1: Median | F1: TI | G1: Quantile | H1: CyclicLoess | I1: VSN | J1: RLR | K1: Final
A2: 75 | B2: PXD016670 | C2: 4 | D2: 3 | E2: 2 | F2: 3 | G2: 1 | H2: 1 | I2: 1 | J2: 1 | K2: Quantile
A3: 11 | B3: PXD038236 | C3: 4 | D3: 5 | E3: 3 | F3: 5 | G3: 2 | H3: 1 | I3: 1 | J3: 1 | K3: CyclicLoess
A4: 17 | B4: PXD054553 | C4: 3 | D4: 2 | E4: 1 | F4: 2 | G4: 1 | H4: 1 | I4: 1 | J4: 1 | K4: Quantile
A5: 98 | B5: PXD005847 | C5: 6 | D5: 5 | E5: 4 | F5: 5 | G5: 3 | H5: 1 | I5: 2 | J5: 2 | K5: CyclicLoess
A6: 72 | B6: PXD012431 | C6: 5 | D6: 4 | E6: 2 | F6: 4 | G6: 3 | H6: 1 | I6: 1 | J6: 1 | K6: CyclicLoess
A7: 15 | B7: PXD022614 | C7: 3 | D7: 2 | E7: 1 | F7: 2 | G7: 1 | H7: 1 | I7: 1 | J7: 1 | K7: Median
A8: 5 | B8: PXD066495 | C8: 2 | D8: 1 | E8: 1 | F8: 1 | G8: 1 | H8: 1 | I8: 1 | J8: 1 | K8: Median
A9: 6 | B9: PXD065898 | C9: 5 | D9: 4 | E9: 3 | F9: 4 | G9: 2 | H9: 1 | I9: 1 | J9: 1 | K9: CyclicLoess
A10: 96 | B10: PXD062946 | C10: 5 | D10: 4 | E10: 3 | F10: 4 | G10: 2 | H10: 1 | I10: 2 | J10: 1 | K10: CyclicLoess
A11: 4 | B11: PXD031710 | C11: 3 | D11: 2 | E11: 1 | F11: 2 | G11: 1 | H11: 1 | I11: 1 | J11: 1 | K11: Quantile
A12: 20 | B12: PXD047566 | C12: 4 | D12: 3 | E12: 2 | F12: 3 | G12: 1 | H12: 1 | I12: 1 | J12: 1 | K12: Quantile
A13: 76 | B13: PXD019139 | C13: 4 | D13: 3 | E13: 2 | F13: 3 | G13: 1 | H13: 1 | I13: 1 | J13: 1 | K13: Quantile
... A101: 38 | B101: PXD060921 | C101: 2 | D101: 3 | E101: 1 | F101: 3 | G101: 1 | H101: 1 | I101: 1 | J101: 1 | K101: Median

Sheet Item6
A1: Number | B1: ID | C1: Log | D1: Mean | E1: Median | F1: TI | G1: Quantile | H1: CyclicLoess | I1: VSN | J1: RLR | K1: Final
A2: 75 | B2: PXD016670 | C2: 3 | D2: 2 | E2: 2 | F2: 2 | G2: 1 | H2: 2 | I2: 2 | J2: 2 | K2: Quantile
A3: 11 | B3: PXD038236 | C3: 3 | D3: 4 | E3: 2 | F3: 4 | G3: 1 | H3: 2 | I3: 2 | J3: 2 | K3: Quantile
A4: 17 | B4: PXD054553 | C4: 5 | D4: 3 | E4: 2 | F4: 3 | G4: 1 | H4: 2 | I4: 2 | J4: 4 | K4: Quantile
A5: 98 | B5: PXD005847 | C5: 6 | D5: 5 | E5: 5 | F5: 5 | G5: 1 | H5: 2 | I5: 3 | J5: 4 | K5: Quantile
A6: 72 | B6: PXD012431 | C6: 7 | D6: 6 | E6: 3 | F6: 6 | G6: 1 | H6: 5 | I6: 4 | J6: 2 | K6: Quantile
A7: 15 | B7: PXD022614 | C7: 4 | D7: 3 | E7: 2 | F7: 3 | G7: 1 | H7: 2 | I7: 2 | J7: 2 | K7: Quantile
A8: 5 | B8: PXD066495 | C8: 2 | D8: 1 | E8: 1 | F8: 1 | G8: 1 | H8: 1 | I8: 1 | J8: 1 | K8: Median
A9: 6 | B9: PXD065898 | C9: 3 | D9: 2 | E9: 1 | F9: 2 | G9: 1 | H9: 1 | I9: 1 | J9: 1 | K9: Median
A10: 96 | B10: PXD062946 | C10: 4 | D10: 3 | E10: 2 | F10: 3 | G10: 1 | H10: 2 | I10: 2 | J10: 2 | K10: Quantile
A11: 4 | B11: PXD031710 | C11: 5 | D11: 4 | E11: 2 | F11: 4 | G11: 1 | H11: 2 | I11: 3 | J11: 2 | K11: Quantile
A12: 20 | B12: PXD047566 | C12: 4 | D12: 3 | E12: 2 | F12: 3 | G12: 1 | H12: 2 | I12: 2 | J12: 2 | K12: Quantile
A13: 76 | B13: PXD019139 | C13: 2 | D13: 1 | E13: 1 | F13: 1 | G13: 1 | H13: 1 | I13: 1 | J13: 1 | K13: Median
... A101: 38 | B101: PXD060921 | C101: 3 | D101: 3 | E101: 2 | F101: 3 | G101: 1 | H101: 2 | I101: 2 | J101: 2 | K101: Quantile

Sheet Old_Item5
A1: Number | B1: ID | C1: Log | D1: Mean | E1: Median | F1: TI | G1: Quantile | H1: CyclicLoess | I1: VSN | J1: RLR | K1: Final
A2: 75 | B2: PXD016670 | C2: 1 | D2: 1 | E2: 1 | F2: 1 | G2: 1 | H2: 1 | I2: 1 | J2: 1 | K2: Log
A3: 11 | B3: PXD038236 | C3: 1 | D3: 1 | E3: 1 | F3: 1 | G3: 1 | H3: 1 | I3: 1 | J3: 1 | K3: Log
A4: 17 | B4: PXD054553 | C4: 5 | D4: 4 | E4: 1 | F4: 4 | G4: 1 | H4: 2 | I4: 2 | J4: 3 | K4: Median
A5: 98 | B5: PXD005847 | C5: 5 | D5: 4 | E5: 3 | F5: 4 | G5: 1 | H5: 2 | I5: 3 | J5: 3 | K5: Quantile
A6: 72 | B6: PXD012431 | C6: 6 | D6: 5 | E6: 2 | F6: 5 | G6: 1 | H6: 4 | I6: 4 | J6: 3 | K6: Quantile
A7: 15 | B7: PXD022614 | C7: 2 | D7: 1 | E7: 1 | F7: 1 | G7: 1 | H7: 1 | I7: 1 | J7: 1 | K7: Median
A8: 5 | B8: PXD066495 | C8: 1 | D8: 1 | E8: 1 | F8: 1 | G8: 1 | H8: 1 | I8: 1 | J8: 1 | K8: Log
A9: 6 | B9: PXD065898 | C9: 3 | D9: 2 | E9: 1 | F9: 2 | G9: 1 | H9: 1 | I9: 1 | J9: 1 | K9: Median
A10: 96 | B10: PXD062946 | C10: 3 | D10: 2 | E10: 1 | F10: 2 | G10: 1 | H10: 1 | I10: 1 | J10: 1 | K10: Median
A11: 4 | B11: PXD031710 | C11: 3 | D11: 2 | E11: 1 | F11: 2 | G11: 1 | H11: 1 | I11: 1 | J11: 1 | K11: Median
A12: 20 | B12: PXD047566 | C12: 3 | D12: 2 | E12: 1 | F12: 2 | G12: 1 | H12: 1 | I12: 1 | J12: 1 | K12: Median
A13: 76 | B13: PXD019139 | C13: 1 | D13: 1 | E13: 1 | F13: 1 | G13: 1 | H13: 1 | I13: 1 | J13: 1 | K13: Log
... A101: 38 | B101: PXD060921 | C101: 1 | D101: 1 | E101: 1 | F101: 1 | G101: 1 | H101: 1 | I101: 1 | J101: 1 | K101: Log
